<robot name="airobot">
    <link name="drone">
        <inertial>
            <origin xyz="-0.000648 -0.000166 0.084487" rpy="0 0 0"/>
            <mass value="1"/>
            <inertia ixx="0.004622" ixy="9E-06" ixz="6E-05" iyy="0.004495" iyz="9E-06" izz="0.002079"/>
        </inertial>
        <visual>
            <origin xyz="0 0 0" rpy="0 0 0"/>
            <geometry>
                <mesh filename="airobot.dae"/>
            </geometry>
        </visual>
        <collision>
            <origin xyz="0 0 0" rpy="0 0 0"/>
            <geometry>
                <mesh filename="airobot.dae"/>
            </geometry>
        </collision>
    </link>
 
    <link name="armA">
        <inertial>
            <origin xyz="-2.3E-05 -0.010364 -0.07336" rpy="0 0 0"/>
            <mass value="0.25" />
            <inertia ixx="0.00457" ixy="1E-06" ixz="2E-06" iyy="0.004831" iyz="0.000448" izz="0.001409"/>
        </inertial>
        <visual>
            <origin xyz="0 0 0" rpy="0 0 0"/>
            <geometry>
                <mesh filename="airobot_grip/armA.obj"/>
            </geometry>
        </visual>
    </link>
    <link name="armB">
        <inertial>
            <origin xyz="2.3E-05 -0.010364 0.07336" rpy="0 0 0"/>
            <mass value="0.25" />
            <inertia ixx="0.00457" ixy="1E-06" ixz="2E-06" iyy="0.004831" iyz="0.000448" izz="0.001409"/>
        </inertial>
        <visual>
            <origin xyz="0 0 0" rpy="0 0 0"/>
            <geometry>
                <mesh filename="airobot_grip/armB.obj"/>
            </geometry>
        </visual>
    </link>

    <joint name="jointBodyArmA" type="continuous">
        <parent link="drone"/>
        <child link="armA"/>
        <origin xyz="0 -0.34 -0.44" rpy="0 0 0"/>
   </joint>

    <joint name="jointBodyArmB" type="continuous">
        <parent link="drone"/>
        <child link="armB"/>
        <origin xyz="0 0.34 -0.49" rpy="0 0 0"/>
    </joint>
</robot>
