<robot name="airobot">
    <link name="world"/>
    <joint name="Fix_world" type="fixed">
        <parent link="world"/>
        <child link="drone"/>
    </joint>
    
    <link name="drone">
        <inertial>
            <origin xyz="-0.000648 -0.000166 0.084487" rpy="0 0 0"/>
            <mass value="1"/>
            <inertia ixx="0.004622" ixy="9E-06" ixz="6E-05" iyy="0.004495" iyz="9E-06" izz="0.002079"/>
        </inertial>
        <visual>
            <origin xyz="0 0 0" rpy="0 0 0"/>
            <geometry>
                <mesh filename="airobot_grip/drone.obj"/>
            </geometry>
        </visual>
        <collision>
            <origin xyz="0 0 0" rpy="0 0 0"/>
            <geometry>
                <mesh filename="airobot_grip/drone.obj"/>
            </geometry>
        </collision>
    </link>
 
    <link name="armA">
        <inertial>
            <origin xyz="-0.000648 -0.000166 0.084487" rpy="0 0 0"/>
            <mass value="0.25"/>
            <inertia ixx="0.00457" ixy="1E-06" ixz="2E-06" iyy="0.004831" iyz="0.000448" izz="0.001409"/>
        </inertial>
        <visual>
            <origin xyz="0 0.005 0.011" rpy="0 0 0"/>
            <geometry>
                <mesh filename="airobot_grip/armA.obj"/>
            </geometry>
        </visual>
    </link>
    <link name="armB">
        <inertial>
            <origin xyz="-0.000648 -0.000166 0.084487" rpy="0 0 0"/>
            <mass value="0.25"/>
            <inertia ixx="0.00457" ixy="1E-06" ixz="2E-06" iyy="0.004831" iyz="0.000448" izz="0.001409"/>
        </inertial>
        <visual>
            <origin xyz="0 0.005 -0.011" rpy="0 0 0"/>
            <geometry>
                <mesh filename="airobot_grip/armB.obj"/>
            </geometry>
        </visual>
    </link>

    <joint name="jointBodyArmA" type="continuous">
        <parent link="drone"/>
        <child link="armA"/>
        <origin xyz="0 0.005 0.011" rpy="0 0 0"/>
   </joint>

    <joint name="jointBodyArmB" type="continuous">
        <parent link="drone"/>
        <child link="armB"/>
        <origin xyz="0 0.005 -0.011" rpy="0 0 0"/>
    </joint>
    <klampt world_frame="world" default_acc_max="1.0">
    <noselfcollision group1="drone" group2="armA armB"/>

    <mount link="drone" file = "airobot_grip.rob" transform = "1 0 0  0 1 0  0 0 1  0 0 0" prefix="gripper"/>
  </klampt>
</robot>
